Workbook
Name rq: Transport!$C:$C
Name tg: Transport!$F$192:$H$197

Sheet CADRAN
B1: VARIATIONS MENSUELLES | C1: PRODUCTIONS | J1: TRANSPORTS
C2: PRIMAIRE | D2: =Primaire!B4 -> Abattages contrôlés de viande | E2: =Primaire!B164 -> 2190.384 | F2: SECONDAIRE | G2: OR | H2: ='Secteur Secondaire'!J164 -> 1167.3686 | J2: AERIEN | K2: Mouvements d'aéronefs | L2: =Transport!$B$164 -> 2549 | M2: MARITIME | N2: EMBARQUEMENTS | O2: =+Transport!J163 -> 419.953
D3: flèche hausse | E3: =IF(Primaire!$B$2<0,0.5,0.49) -> 0.5 | G3: flèche hausse | H3: =IF('Secteur Secondaire'!$J$3<0,0.5,0.49) -> 0.5 | K3: flèche hausse | L3: =IF(Transport!$B$2<0,0.5,0.49) -> 0.5 | N3: flèche hausse | O3: =IF(Transport!$J$2<0,0.5,0.49) -> 0.49
D4: flèche baisse | E4: =IF(Primaire!$B$2>0,0.5,0.49) -> 0.49 | G4: flèche baisse | H4: =IF('Secteur Secondaire'!$J$3>0,0.5,0.49) -> 0.49 | K4: flèche baisse | L4: =IF(Transport!$B$2>0,0.5,0.49) -> 0.49 | N4: flèche baisse | O4: =IF(Transport!$J$2>0,0.5,0.49) -> 0.5
A5: ENVIRONNEMENT INTERNATIONAL | D5: Variation | E5: =Primaire!$B$2 -> -0.14275371 | G5: Variation | H5: ='Secteur Secondaire'!$J$3 -> -0.24958542 | K5: Variation | L5: =Transport!$B$2 -> -0.040300277 | N5: Variation | O5: =Transport!$J$2 -> 0.01865368
A6: Cours du baril | B6: ='Environnement International'!G163 -> 59.27 | G6: PHOSPHATE | H6: ='Secteur Secondaire'!C164 -> 132.524
A7: flèche hausse | B7: =IF('Environnement International'!$G$3<0,0.5,0.49) -> 0.49 | D7: =Primaire!C4 -> Pêche | E7: =Primaire!C164 -> 47975.904 | G7: flèche hausse | H7: =IF('Secteur Secondaire'!$C$3<0,0.5,0.49) -> 0.5 | K7: PASSAGERS | L7: =Transport!$C$164 -> 195624
A8: flèche baisse | B8: =IF('Environnement International'!$G$3>0,0.5,0.49) -> 0.5 | D8: flèche hausse | E8: =IF(Primaire!$C$2<0,0.5,0.49) -> 0.49 | G8: flèche baisse | H8: =IF('Secteur Secondaire'!$C$3>0,0.5,0.49) -> 0.49 | K8: flèche hausse | L8: =IF(Transport!$C$2<0,0.5,0.49) -> 0.49
A9: Variation | B9: ='Environnement International'!$G$3 -> 0.064508929 | D9: flèche baisse | E9: =IF(Primaire!$C$2>0,0.5,0.49) -> 0.5 | G9: Variation | H9: ='Secteur Secondaire'!$C$3 -> -0.061808271 | K9: flèche baisse | L9: =IF(Transport!$C$2>0,0.5,0.49) -> 0.5
D10: Variation | E10: =Primaire!$C$2 -> 0.10355542 | K10: Variation | L10: =Transport!$C$2 -> 0.024612402
N11: DEBARQUEMENTS | O11: =Transport!N163 -> 934.739
A12: ='[1]Environnement International'!B25 -> COURS EURO / DOLLAR USA | B12: ='Environnement International'!K163 -> 1.1416 | G12: CIMENT | H12: ='Secteur Secondaire'!R164 -> 559.47708 | K12: FRET | L12: =Transport!$G$164 -> 3040.38 | N12: flèche hausse | O12: =IF(Transport!$N$2<0,0.5,0.49) -> 0.5
A13: flèche hausse | B13: =IF('Environnement International'!$K$3<0,0.5,0.49) -> 0.49 | G13: flèche hausse | H13: =IF('Secteur Secondaire'!$R$3<0,0.5,0.49) -> 0.5 | K13: flèche hausse | L13: =IF(Transport!$G$2<0,0.5,0.49) -> 0.49 | N13: flèche baisse | O13: =IF(Transport!$N$2>0,0.5,0.49) -> 0.49
A14: flèche baisse | B14: =IF('Environnement International'!$K$3>0,0.5,0.49) -> 0.5 | G14: flèche baisse | H14: =IF('Secteur Secondaire'!$R$3>0,0.5,0.49) -> 0.49 | K14: flèche baisse | L14: =IF(Transport!$G$2>0,0.5,0.49) -> 0.5 | N14: Variation | O14: =Transport!$N$2 -> -0.20512644
A15: Variation | B15: ='Environnement International'!$K$3 -> 0.0024767273 | G15: Variation | H15: ='Secteur Secondaire'!$R$3 -> -0.048948199 | K15: Variation | L15: =Transport!$G$2 -> 0.14355908
A16: FINANCES PUBLIQUES | C16: INDICES DU CHIFFRE D'AFFAIRES BRUTS ET CORRIGES DES VARIATIONS SAISONNIERES | J16: COMMERCE EXTERIEUR
A17: (en milliards de FCFA) | B17: Janv | C17: PRIMAIRE | F17: SECONDAIRE | J17: IMPORTATIONS | K17: RIZ | L17: ='Commerce Extérieur'!B164 -> 112.59619 | M17: EXPORTATIONS | N17: PRODUITS ARACHIDIERS | O17: ='Commerce Extérieur'!F164 -> 30.70379
A18: Réalisations 2026 | B18: =graphes!O5 -> 339.34355 | K18: flèche hausse | L18: =IF('Commerce Extérieur'!$B$3<0,0.5,0.49) -> 0.5 | N18: flèche hausse | O18: =IF('Commerce Extérieur'!$F$3<0,0.5,0.49) -> 0.5
A19: Situation 2025 | B19: =graphes!O6 -> 304.16192 | K19: flèche baisse | L19: =IF('Commerce Extérieur'!$B$3>0,0.5,0.49) -> 0.49 | N19: flèche baisse | O19: =IF('Commerce Extérieur'!$F$3>0,0.5,0.49) -> 0.49
A20: Plus ou moins value | B20: =B18-B19 -> 35.181632 | K20: Variation | L20: ='Commerce Extérieur'!$B$3 -> -0.036034591 | N20: Variation | O20: ='Commerce Extérieur'!$F$3 -> -1
A21: flèche hausse | B21: =IF(B18-B19>0,0.5,0.49) -> 0.5
A22: flèche baisse | B22: =IF(B18-B19<0,0.5,0.49) -> 0.49 | K22: PETROLE BRUT | L22: ='Commerce Extérieur'!D164 -> 128.13635
K23: flèche hausse | L23: =IF('Commerce Extérieur'!$D$3<0,0.5,0.49) -> 0.5
C24: COMMERCE | F24: SERVICES | K24: flèche baisse | L24: =IF('Commerce Extérieur'!$D$3>0,0.5,0.49) -> 0.49
K25: Variation | L25: ='Commerce Extérieur'!$D$3 -> -1 | N25: PECHE | O25: ='Commerce Extérieur'!H164 -> 23.638
N26: flèche hausse | O26: =IF('Commerce Extérieur'!$H$3<0,0.5,0.49) -> 0.49
K27: PETROLE RAFFINE | L27: ='Commerce Extérieur'!E164 -> 124.97819 | N27: flèche baisse | O27: =IF('Commerce Extérieur'!$H$3>0,0.5,0.49) -> 0.5
K28: flèche hausse | L28: =IF('Commerce Extérieur'!$E$3<0,0.5,0.49) -> 0.49 | N28: Variation | O28: ='Commerce Extérieur'!$H$3 -> 0.35366649
K29: flèche baisse | L29: =IF('Commerce Extérieur'!$E$3>0,0.5,0.49) -> 0.5
K30: Variation | L30: ='Commerce Extérieur'!$E$3 -> 0.52063668
S33: c

Sheet graphes
A1: Dates | B1: Primaire brute | C1: Prim_CVS | E1: Secondaire brute | F1: Sec_CVS | H1: Services brute | I1: Sces_CVS | K1: Commerce brute | L1: Cce_CVS | N1: Finances Publiques
A2: =Primaire!A127 -> 42370 | B2: =Primaire!H127 -> 314.8191 | C2: =#REF! -> #REF! | E2: ='Indice Secondaire'!B7 -> 50.653394 | F2: =#REF! -> #REF! | H2: ='ICAS et ICAC'!C115 -> 82.427167 | I2: =#REF! -> #REF! | K2: ='ICAS et ICAC'!AO115 -> 46.548084 | L2: =#REF! -> #REF!
A3: =Primaire!A128 -> 42401 | B3: =Primaire!H128 -> 306.07246 | C3: =#REF! -> #REF! | E3: ='Indice Secondaire'!B8 -> 49.54939 | F3: =#REF! -> #REF! | H3: ='ICAS et ICAC'!C116 -> 88.269933 | I3: =#REF! -> #REF! | K3: ='ICAS et ICAC'!AO116 -> 46.677612 | L3: =#REF! -> #REF! | N3: MOIS
A4: =Primaire!A129 -> 42430 | B4: =Primaire!H129 -> 311.62873 | C4: =#REF! -> #REF! | E4: ='Indice Secondaire'!B9 -> 56.567739 | F4: =#REF! -> #REF! | H4: ='ICAS et ICAC'!C117 -> 85.365894 | I4: =#REF! -> #REF! | K4: ='ICAS et ICAC'!AO117 -> 52.553564 | L4: =#REF! -> #REF!
A5: =Primaire!A130 -> 42461 | B5: =Primaire!H130 -> 308.24261 | C5: =#REF! -> #REF! | E5: ='Indice Secondaire'!B10 -> 52.171553 | F5: =#REF! -> #REF! | H5: ='ICAS et ICAC'!C118 -> 94.825274 | I5: =#REF! -> #REF! | K5: ='ICAS et ICAC'!AO118 -> 49.695327 | L5: =#REF! -> #REF! | N5: Réalisations | O5: 339.34355 | P5: =O5/O6 -> 1.1156674
A6: =Primaire!A131 -> 42491 | B6: =Primaire!H131 -> 322.15279 | C6: =#REF! -> #REF! | E6: ='Indice Secondaire'!B11 -> 57.916839 | F6: =#REF! -> #REF! | H6: ='ICAS et ICAC'!C119 -> 89.621283 | I6: =#REF! -> #REF! | K6: ='ICAS et ICAC'!AO119 -> 51.283739 | L6: =#REF! -> #REF! | N6: Objectif | O6: 304.16192 | P6: =P7-P5 -> -0.11566744
A7: =Primaire!A132 -> 42522 | B7: =Primaire!H132 -> 281.72882 | C7: =#REF! -> #REF! | E7: ='Indice Secondaire'!B12 -> 57.374722 | F7: =#REF! -> #REF! | H7: ='ICAS et ICAC'!C120 -> 89.2359 | I7: =#REF! -> #REF! | K7: ='ICAS et ICAC'!AO120 -> 51.228262 | L7: =#REF! -> #REF! | N7: Invisible | O7: =SUM(O5:O6) -> 643.50548 | P7: 1
A8: =Primaire!A133 -> 42552 | B8: =Primaire!H133 -> 317.56455 | C8: =#REF! -> #REF! | E8: ='Indice Secondaire'!B13 -> 61.154547 | F8: =#REF! -> #REF! | H8: ='ICAS et ICAC'!C121 -> 94.623197 | I8: =#REF! -> #REF! | K8: ='ICAS et ICAC'!AO121 -> 47.626473 | L8: =#REF! -> #REF!
A9: =Primaire!A134 -> 42583 | B9: =Primaire!H134 -> 312.35879 | C9: =#REF! -> #REF! | E9: ='Indice Secondaire'!B14 -> 58.312721 | F9: =#REF! -> #REF! | H9: ='ICAS et ICAC'!C122 -> 90.753064 | I9: =#REF! -> #REF! | K9: ='ICAS et ICAC'!AO122 -> 47.897653 | L9: =#REF! -> #REF! | N9: aiguille | O9: =O5 -> 339.34355 | P9: =P5 -> 1.1156674
A10: =Primaire!A135 -> 42614 | B10: =Primaire!H135 -> 202.71898 | C10: =#REF! -> #REF! | E10: ='Indice Secondaire'!B15 -> 50.847476 | F10: =#REF! -> #REF! | H10: ='ICAS et ICAC'!C123 -> 91.592298 | I10: =#REF! -> #REF! | K10: ='ICAS et ICAC'!AO123 -> 45.538777 | L10: =#REF! -> #REF! | N10: largeur | O10: 3 | P10: 0.01
A11: =Primaire!A136 -> 42644 | B11: =Primaire!H136 -> 275.11504 | C11: =#REF! -> #REF! | E11: ='Indice Secondaire'!B16 -> 51.058351 | F11: =#REF! -> #REF! | H11: ='ICAS et ICAC'!C124 -> 88.510846 | I11: =#REF! -> #REF! | K11: ='ICAS et ICAC'!AO124 -> 47.09186 | L11: =#REF! -> #REF! | N11: Invisible | O11: =SUM(O5:O7)-SUM(O9:O10) -> 944.6674 | P11: =SUM(P5:P7)-SUM(P9:P10) -> 0.87433256
A12: =Primaire!A137 -> 42675 | B12: =Primaire!H137 -> 281.81392 | C12: =#REF! -> #REF! | E12: ='Indice Secondaire'!B17 -> 54.808174 | F12: =#REF! -> #REF! | H12: ='ICAS et ICAC'!C125 -> 110.68189 | I12: =#REF! -> #REF! | K12: ='ICAS et ICAC'!AO125 -> 54.02791 | L12: =#REF! -> #REF!
A13: =Primaire!A138 -> 42705 | B13: =Primaire!H138 -> 344.51126 | C13: =#REF! -> #REF! | E13: ='Indice Secondaire'!B18 -> 60.10097 | F13: =#REF! -> #REF! | H13: ='ICAS et ICAC'!C126 -> 110.68189 | I13: =#REF! -> #REF! | K13: ='ICAS et ICAC'!AO126 -> 58.819748 | L13: =#REF! -> #REF!
A14: =Primaire!A139 -> 42736 | B14: =Primaire!H139 -> 311.58575 | C14: =#REF! -> #REF! | E14: ='Indice Secondaire'!B19 -> 48.367178 | F14: =#REF! -> #REF! | H14: ='ICAS et ICAC'!C127 -> 89.646317 | I14: =#REF! -> #REF! | K14: ='ICAS et ICAC'!AO127 -> 55.809808 | L14: =#REF! -> #REF!
A15: =Primaire!A140 -> 42767 | B15: =Primaire!H140 -> 291.5687 | C15: =#REF! -> #REF! | E15: ='Indice Secondaire'!B20 -> 50.698895 | F15: =#REF! -> #REF! | H15: ='ICAS et ICAC'!C128 -> 85.229786 | I15: =#REF! -> #REF! | K15: ='ICAS et ICAC'!AO128 -> 54.830954 | L15: =#REF! -> #REF!
A16: =Primaire!A141 -> 42795 | B16: =Primaire!H141 -> 325.34686 | C16: =#REF! -> #REF! | E16: ='Indice Secondaire'!B21 -> 53.823284 | F16: =#REF! -> #REF! | H16: ='ICAS et ICAC'!C129 -> 90.618834 | I16: =#REF! -> #REF! | K16: ='ICAS et ICAC'!AO129 -> 59.332935 | L16: =#REF! -> #REF!
A17: =Primaire!A142 -> 42826 | B17: =Primaire!H142 -> 330.60769 | C17: =#REF! -> #REF! | E17: ='Indice Secondaire'!B22 -> 49.566802 | F17: =#REF! -> #REF! | H17: ='ICAS et ICAC'!C130 -> 90.146117 | I17: =#REF! -> #REF! | K17: ='ICAS et ICAC'!AO130 -> 56.699295 | L17: =#REF! -> #REF!
A18: =Primaire!A143 -> 42856 | B18: =Primaire!H143 -> 338.70057 | C18: =#REF! -> #REF! | E18: ='Indice Secondaire'!B23 -> 58.431244 | F18: =#REF! -> #REF! | H18: ='ICAS et ICAC'!C131 -> 88.671367 | I18: =#REF! -> #REF! | K18: ='ICAS et ICAC'!AO131 -> 57.894833 | L18: =#REF! -> #REF! | N18: ANNEE
A19: =Primaire!A144 -> 42887 | B19: =Primaire!H144 -> 294.97839 | C19: =#REF! -> #REF! | E19: ='Indice Secondaire'!B24 -> 57.791939 | F19: =#REF! -> #REF! | H19: ='ICAS et ICAC'!C132 -> 92.117849 | I19: =#REF! -> #REF! | K19: ='ICAS et ICAC'!AO132 -> 59.426002 | L19: =#REF! -> #REF!
A20: =Primaire!A145 -> 42917 | B20: =Primaire!H145 -> 315.16493 | C20: =#REF! -> #REF! | E20: ='Indice Secondaire'!B25 -> 48.924652 | F20: =#REF! -> #REF! | H20: ='ICAS et ICAC'!C133 -> 91.878546 | I20: =#REF! -> #REF! | K20: ='ICAS et ICAC'!AO133 -> 59.839201 | L20: =#REF! -> #REF! | N20: Réalisations | O20: ='Finances Publiques '!B171 -> 1810.43
A21: =Primaire!A146 -> 42948 | B21: =Primaire!H146 -> 300.36126 | C21: =#REF! -> #REF! | E21: ='Indice Secondaire'!B26 -> 51.465988 | F21: =#REF! -> #REF! | H21: ='ICAS et ICAC'!C134 -> 97.625146 | I21: =#REF! -> #REF! | K21: ='ICAS et ICAC'!AO134 -> 56.714575 | L21: =#REF! -> #REF! | N21: LFI 2019 | O21: 2657.4
A22: =Primaire!A147 -> 42979 | B22: =Primaire!H147 -> 214.39966 | C22: =#REF! -> #REF! | E22: ='Indice Secondaire'!B27 -> 49.380612 | F22: =#REF! -> #REF! | H22: ='ICAS et ICAC'!C135 -> 90.888213 | I22: =#REF! -> #REF! | K22: ='ICAS et ICAC'!AO135 -> 58.229834 | L22: =#REF! -> #REF! | N22: Invisible | O22: =SUM(O20:O21) -> 4467.83
A23: =Primaire!A148 -> 43009 | B23: =Primaire!H148 -> 297.17798 | C23: =#REF! -> #REF! | E23: ='Indice Secondaire'!B28 -> 49.743875 | F23: =#REF! -> #REF! | H23: ='ICAS et ICAC'!C136 -> 87.866075 | I23: =#REF! -> #REF! | K23: ='ICAS et ICAC'!AO136 -> 62.947106 | L23: =#REF! -> #REF!
A24: =Primaire!A149 -> 43040 | B24: =Primaire!H149 -> 333.64589 | C24: =#REF! -> #REF! | E24: ='Indice Secondaire'!B29 -> 51.427978 | F24: =#REF! -> #REF! | H24: ='ICAS et ICAC'!C137 -> 95.741008 | I24: =#REF! -> #REF! | K24: ='ICAS et ICAC'!AO137 -> 66.062313 | L24: =#REF! -> #REF!
A25: =Primaire!A150 -> 43070 | B25: =Primaire!H150 -> 361.70796 | C25: =#REF! -> #REF! | E25: ='Indice Secondaire'!B30 -> 55.640721 | F25: =#REF! -> #REF! | H25: ='ICAS et ICAC'!C138 -> 94.866296 | I25: =#REF! -> #REF! | K25: ='ICAS et ICAC'!AO138 -> 66.336591 | L25: =#REF! -> #REF!
A26: =Primaire!A151 -> 43101 | B26: =Primaire!H151 -> 346.83061 | C26: =#REF! -> #REF! | E26: ='Indice Secondaire'!B31 -> 49.027265 | F26: =#REF! -> #REF! | H26: ='ICAS et ICAC'!C139 -> 96.229927 | I26: =#REF! -> #REF! | K26: ='ICAS et ICAC'!AO139 -> 61.217494 | L26: =#REF! -> #REF!
A27: =Primaire!A152 -> 43132 | B27: =Primaire!H152 -> 322.77404 | C27: =#REF! -> #REF! | E27: ='Indice Secondaire'!B32 -> 49.49962 | F27: =#REF! -> #REF! | H27: ='ICAS et ICAC'!C140 -> 92.53842 | I27: =#REF! -> #REF! | K27: ='ICAS et ICAC'!AO140 -> 63.652574 | L27: =#REF! -> #REF!
A28: =Primaire!A153 -> 43160 | B28: =Primaire!H153 -> 375.21534 | C28: =#REF! -> #REF! | E28: ='Indice Secondaire'!B33 -> 55.996609 | F28: =#REF! -> #REF! | H28: ='ICAS et ICAC'!C141 -> 92.693022 | I28: =#REF! -> #REF! | K28: ='ICAS et ICAC'!AO141 -> 62.147878 | L28: =#REF! -> #REF!
A29: =Primaire!A154 -> 43191 | B29: =Primaire!H154 -> 358.33769 | C29: =#REF! -> #REF! | E29: ='Indice Secondaire'!B34 -> 53.190612 | F29: =#REF! -> #REF! | H29: ='ICAS et ICAC'!C142 -> 92.079512 | I29: =#REF! -> #REF! | K29: ='ICAS et ICAC'!AO142 -> 61.634925 | L29: =#REF! -> #REF!
A30: =Primaire!A155 -> 43221 | B30: =Primaire!H155 -> 343.90641 | C30: =#REF! -> #REF! | E30: ='Indice Secondaire'!B35 -> 60.560516 | F30: =#REF! -> #REF! | H30: ='ICAS et ICAC'!C143 -> 96.138391 | I30: =#REF! -> #REF! | K30: ='ICAS et ICAC'!AO143 -> 65.861987 | L30: =#REF! -> #REF!
A31: =Primaire!A156 -> 43252 | B31: =Primaire!H156 -> 334.5421 | C31: =#REF! -> #REF! | E31: ='Indice Secondaire'!B36 -> 55.389781 | F31: =#REF! -> #REF! | H31: ='ICAS et ICAC'!C144 -> 97.981845 | I31: =#REF! -> #REF! | K31: ='ICAS et ICAC'!AO144 -> 61.847001 | L31: =#REF! -> #REF!
A32: =Primaire!A157 -> 43282 | B32: =Primaire!H157 -> 321.84621 | C32: =#REF! -> #REF! | E32: ='Indice Secondaire'!B37 -> 57.849911 | F32: =#REF! -> #REF! | H32: ='ICAS et ICAC'!C145 -> 99.590283 | I32: =#REF! -> #REF! | K32: ='ICAS et ICAC'!AO145 -> 65.338899 | L32: =#REF! -> #REF!
A33: =Primaire!A158 -> 43313 | B33: =Primaire!H158 -> 261.85722 | C33: =#REF! -> #REF! | E33: ='Indice Secondaire'!B38 -> 55.851854 | F33: =#REF! -> #REF! | H33: ='ICAS et ICAC'!C146 -> 94.106023 | I33: =#REF! -> #REF! | K33: ='ICAS et ICAC'!AO146 -> 64.518521 | L33: =#REF! -> #REF!
A34: =Primaire!A159 -> 43344 | B34: =Primaire!H159 -> 256.9084 | C34: =#REF! -> #REF! | E34: ='Indice Secondaire'!B39 -> 54.484074 | F34: =#REF! -> #REF! | H34: ='ICAS et ICAC'!C147 -> 95.573004 | I34: =#REF! -> #REF! | K34: ='ICAS et ICAC'!AO147 -> 61.992498 | L34: =#REF! -> #REF!
... A121: =Primaire!A246 -> 45992 | B121: =Primaire!H246 -> 123.47314 | C121: =#REF! -> #REF! | E121: ='Indice Secondaire'!B126 -> 120.19417 | F121: =#REF! -> #REF! | H121: ='ICAS et ICAC'!C234 -> 148.17683 | I121: =#REF! -> #REF! | K121: ='ICAS et ICAC'!AO234 -> 103.79187 | L121: =#REF! -> #REF!
A122: =Primaire!A247 -> 46023 | B122: =Primaire!H247 -> 110.09631 | C122: =#REF! -> #REF! | E122: ='Indice Secondaire'!B128 -> 0 | H122: ='ICAS et ICAC'!C235 -> 123.00144 | K122: ='ICAS et ICAC'!AO235 -> 89.835383

Sheet Environnement International
A1: DIRECTION DE LA PREVISION ET DES ETUDES ECONOMIQUES
B3: =B247/B246-1 -> 0.06267736 | C3: =C247/C246-1 -> 0.024630039 | D3: =D247/D246-1 -> -0.016896056 | E3: =E247/E246-1 -> -0.005872301 | F3: =F247/F246-1 -> 0 | G3: =G247/G246-1 -> 0.064508929 | H3: =H247/H246-1 -> #VALUE! | I3: =I247/I246-1 -> 0 | ... K3: =K247/K246-1 -> 0.0024767273
B4: Cours des matières premières | H4: CHANGES (par rapport au CFA UEMOA) | K4: EURO / DOLLAR USA | L4: Taux d'intérêt nominal (long terme) | P4: Prix à la consommation (glissement sur 12 mois)
B5: Huile d'arachide | C5: Huile de palme | D5: Riz | E5: Maïs | F5: Phosphate | G5: Pétrole, BRENT | H5: 1 DTS = | I5: 1 Euro = | J5: 1 Dollar USA = | L5: France | M5: USA | N5: Allemagne | O5: Japon | P5: USA | Q5: Japon | R5: Allemagne | S5: France | T5: Zone Euro
B6: ($/t) | C6: ($/t) | D6: ($/t) | E6: ($/t) | F6: ($/t) | G6: ($/baril)
A7: 38718 | B7: 930 | C7: 424 | D7: 211 | E7: 102.7 | F7: 42 | G7: 63.6 | H7: 784.44989 | I7: 655.957 | J7: 542.01727 | K7: 1.21 | L7: 3.4 | M7: 4.42 | N7: 3.26 | O7: 1.56 | P7: 4.1 | Q7: 0.5 | R7: 2.1 | S7: 2 | T7: 2.0333333
A8: 38749 | B8: 921 | C8: 445 | D8: 215.3 | E8: 107.1 | F8: 42 | G8: 59.9 | H8: 788.88394 | I8: 655.957 | J8: 549.46894 | K8: 1.19 | L8: 3.56 | M8: 4.57 | N8: 3.4 | O8: 1.58 | P8: 3.6 | Q8: 0.4 | R8: 2.1 | S8: 1.9 | T8: 2.2
A9: 38777 | B9: 902 | C9: 440 | D9: 215 | E9: 105.3 | F9: 43 | G9: 62.3 | H9: 785.38913 | I9: 655.957 | J9: 545.7213 | K9: 1.202 | L9: 3.72 | M9: 4.72 | N9: 3.59 | O9: 1.77 | P9: 3.3 | Q9: 0.3 | R9: 1.8 | S9: 1.5 | T9: 2.3333333
A10: 38808 | B10: 899 | C10: 439 | D10: 216.8 | E10: 107.7 | F10: 43 | G10: 70.4 | H10: 776.09678 | I10: 655.957 | J10: 534.55872 | K10: 1.227 | L10: 4.01 | M10: 4.99 | N10: 3.84 | O10: 1.92 | P10: 3.5 | Q10: 0.4 | R10: 2 | S10: 1.7 | T10: 2.4
A11: 38838 | B11: 892 | C11: 440 | D11: 217.6 | E11: 110.6 | F11: 43 | G11: 70.2 | H11: 765.14289 | I11: 655.957 | J11: 513.71055 | K11: 1.2769 | L11: 4.07 | M11: 5.11 | N11: 3.89 | O11: 1.81 | P11: 4.2 | Q11: 0.6 | R11: 1.9 | S11: 2.1 | T11: 2.2444444
A12: 38869 | B12: 898 | C12: 437 | D12: 215.5 | E12: 109.4 | F12: 44.5 | G12: 68.9 | H12: 766.48399 | I12: 655.957 | J12: 518.58408 | K12: 1.2649 | L12: 4.06 | M12: 5.11 | N12: 3.9 | O12: 1.92 | P12: 4.3 | Q12: 0.5 | R12: 2 | S12: 1.9 | T12: 2.5
A13: 38899 | B13: 928 | C13: 471 | D13: 217.3 | E13: 113.99108 | F13: 45.5 | G13: 74 | H13: 764.3 | I13: 655.957 | J13: 517.2 | K13: 1.269 | L13: 4.09 | M13: 5.09 | N13: 3.96 | O13: 1.92 | P13: 4.1 | Q13: 0.3 | R13: 1.9 | S13: 1.9 | T13: 2.5
A14: 38930 | B14: 944 | C14: 510 | D14: 217.7 | E14: 116.58833 | F14: 45.5 | G14: 73.6 | H14: 761.4 | I14: 655.957 | J14: 512 | K14: 1.28 | L14: 3.96 | M14: 4.88 | N14: 3.85 | O14: 1.61 | P14: 3.8 | Q14: 1 | R14: 1.7 | S14: 1.9 | T14: 2.5
A15: 38961 | B15: 959 | C15: 498 | D15: 222.6 | E15: 121.74554 | F15: 45.5 | G15: 63.575667 | H15: 757 | I15: 655.957 | J15: 515 | K15: 1.27 | L15: 3.84 | M15: 4.72 | N15: 3.75 | O15: 1.66 | P15: 2.1 | Q15: 0.6 | R15: 1 | S15: 1.2 | T15: 2.5
A16: 38991 | B16: 1068 | C16: 506.92042 | D16: 222.3 | E16: 142.2 | F16: 45.5 | G16: 59.63 | H16: 766.48399 | I16: 655.957 | J16: 520.1467 | K16: 1.26 | L16: 3.88 | M16: 4.73 | N16: 3.79 | O16: 1.71 | P16: 1.3 | Q16: 0.3 | R16: 1.1 | S16: 1.1 | T16: 1.6
A17: 39022 | B17: 1120 | C17: 547.02533 | D17: 219 | E17: 164.53856 | F17: 45.5 | G17: 58.634 | H17: 767.56026 | I17: 655.957 | J17: 509.24385 | K17: 1.29 | L17: 3.81 | M17: 4.6 | N17: 3.73 | O17: 1.65 | P17: 1.9 | Q17: 0.1 | R17: 1.5 | S17: 1.4 | T17: 1.6
A18: 39052 | B18: 1173 | C18: 582.94099 | D18: 226.3 | E18: 160.37539 | F18: 45.5 | G18: 62.236667 | H18: 748.6 | I18: 655.957 | J18: 496.48577 | K18: 1.32 | L18: 3.87 | M18: 4.56 | N18: 3.8 | O18: 1.68 | P18: 2.5 | Q18: 0 | R18: 1.4 | S18: 1.5 | T18: 2
... A108: 41791 | B108: 1310 | C108: 857 | D108: 402.6 | E108: 202.4 | F108: 110 | G108: 111.88021 | H108: 740.3 | I108: 655.957 | J108: 482.26329 | K108: 1.3601637 | L108: 1.71 | M108: 2.6 | N108: 1.26 | O108: 0.56 | P108: 2.072 | Q108: 3.607 | R108: 1.042 | S108: 0.486 | T108: 0.494
A109: 41821 | B109: 1325 | C109: 841 | D109: 435.6 | E109: 182.7 | F109: 110 | G109: 108.29016 | H109: 741.6 | I109: 655.957 | J109: 484.58656 | K109: 1.3536426 | L109: 1.56 | M109: 2.54 | N109: 1.11 | O109: _ | P109: 1.992 | Q109: 3.4 | R109: 0.848 | S109: 0.464 | T109: 0.376
A110: 41852 | B110: 1350 | C110: 766 | D110: 460.6 | E110: 176.4 | F110: 110 | G110: 103.59885 | H110: 746.9 | I110: 655.957 | J110: 492.71031 | K110: 1.3313239 | L110: 1.41 | M110: 2.42 | N110: 0.95 | O110: _ | P110: 1.7 | Q110: 3.29 | R110: 0.848 | S110: 0.438 | T110: 0.367
A111: 41883 | B111: 1360 | C111: 709 | D111: 449.9 | E111: 163.1 | F111: 115 | G111: 98.476751 | H111: 757.1 | I111: 655.957 | J111: 509.28602 | K111: 1.2879933 | L111: 1.35 | M111: 2.53 | N111: 0.92 | O111: _ | P111: 1.7 | Q111: 3.2 | R111: 0.848 | S111: 0.29 | T111: 0.314
A112: 41913 | B112: 1365 | C112: 722 | D112: 437.57 | E112: 163.12 | F112: 115 | G112: 88.105484 | H112: 763 | I112: 655.957 | J112: 517.79877 | K112: 1.2668184 | L112: 1.26 | M112: 2.3 | N112: 0.79 | O112: _ | P112: 1.664 | Q112: 2.88 | R112: 0.755 | S112: 0.456 | T112: 0.382
A113: 41944 | B113: 1368 | C113: 731 | D113: 423.8 | E113: 178.74 | F113: 115 | G113: 80.171333 | H113: 767.9 | I113: 655.957 | J113: 526.04157 | K113: 1.246968 | L113: 1.14 | M113: 2.33 | N113: 0.72 | O113: 0.42 | P113: 1.322 | Q113: 2.381 | R113: 0.566 | S113: 0.322 | T113: 0.3
A114: 41974 | B114: 1370 | C114: 693 | D114: 421.18 | E114: 178.73 | F114: 115 | G114: 63.047149 | H114: 771.8 | I114: 655.957 | J114: 533.35894 | K114: 1.2298603 | L114: 0.92 | M114: 2.21 | N114: 0.59 | O114: 0.32 | P114: 0.756 | Q114: 2.379 | R114: 0.188 | S114: 0.071 | T114: -0.169
A115: 42005 | B115: 1391 | C115: 688 | D115: 418.55 | E115: 174.70731 | F115: 115 | G115: 50.18129 | H115: 789.7 | I115: 655.957 | J115: 564.56754 | K115: 1.1618752 | L115: 0.67 | M115: 1.88 | N115: 0.39 | O115: 0.28 | P115: -0.089 | Q115: 2.383 | R115: -0.283 | S115: -0.378 | T115: -0.6
A116: 42036 | B116: 1366 | C116: 689 | D116: 417 | E116: 173.69555 | F116: 115 | G116: 58.747963 | H116: 797.6 | I116: 655.957 | J116: 578.30909 | K116: 1.1342671 | L116: 0.6 | M116: 1.98 | N116: 0.3 | O116: 0.34 | P116: -0.025 | Q116: 2.185 | R116: 0.094 | S116: -0.274 | T116: -0.273
A117: 42064 | B117: 1356 | C117: 672 | D117: 411 | E117: 174.22702 | F117: 115 | G117: 57.173453 | H117: 812.1 | I117: 655.957 | J117: 606.24564 | K117: 1.0819987 | L117: 0.51 | M117: 2.04 | N117: 0.23 | O117: 0.4 | P117: -0.074 | Q117: 2.277 | R117: 0.281 | S117: -0.062 | T117: -0.085
A118: 42095 | B118: 1348 | C118: 662 | D118: 400.26 | E118: 172.05391 | F118: 115 | G118: 60.761 | H118: 813.6 | I118: 655.957 | J118: 606.4822 | K118: 1.0815767 | L118: 0.44 | M118: 1.94 | N118: 0.12 | O118: 0.33 | P118: -0.2 | Q118: 0.582 | R118: 0.469 | S118: 0.094 | T118: 0.008
A119: 42125 | B119: 1345 | C119: 659 | D119: 386.53 | E119: 166.29437 | F119: 115 | G119: 65.541613 | H119: 803.2 | I119: 655.957 | J119: 587.68845 | K119: 1.1161645 | L119: 0.89 | M119: 2.2 | N119: 0.56 | O119: 0.39 | P119: -0.04 | Q119: 0.5 | R119: 0.658 | S119: 0.296 | T119: 0.34
A120: 42156 | B120: 1345 | C120: 671 | D120: 375.95 | E120: 166.71954 | F120: 115 | G120: 63.481638 | H120: 801.4 | I120: 655.957 | J120: 583.99344 | K120: 1.1232267 | L120: 1.2 | M120: 2.36 | N120: 0.79 | O120: 0.45 | P120: 0.12 | Q120: 0.4 | R120: 0.281 | S120: 0.258 | T120: 0.22
A121: 42186 | B121: 1345 | C121: 636 | D121: 389.86 | E121: 179.59682 | F121: 115 | G121: 55.87 | H121: 807 | I121: 655.957 | J121: 596.48958 | K121: 1.0996957 | L121: 1.26 | M121: 2.32 | N121: 0.71 | O121: 0.41 | P121: 0.17 | Q121: 0.2 | R121: 0.19 | S121: 0.16 | T121: 0.23
A122: 42217 | B122: 1331 | C122: 549 | D122: 377.5 | E122: 162.59378 | F122: 115 | G122: 46.99 | H122: 803.6 | I122: 655.957 | J122: 588.88 | K122: 1.1144095 | L122: 1.15 | M122: 2.17 | N122: 0.61 | O122: 0.375 | P122: 0.195 | Q122: 0.2 | R122: 0.187 | S122: 0.047 | T122: 0.127
A123: 42248 | B123: 1321 | C123: 538 | D123: 360 | E123: 165.62118 | F123: 121 | G123: 47.24 | H123: 801.2 | I123: 655.957 | J123: 583.76161 | K123: 1.1236727 | L123: 1.217 | M123: 2.17 | N123: 0.65 | O123: 0.345 | P123: -0.036 | Q123: 0 | R123: 0 | S123: 0.031 | T123: -0.1
A124: 42278 | B124: 1314 | C124: 583 | D124: 369.27 | E124: 171.38859 | F124: 123 | G124: 48.12 | H124: 800.9 | I124: 655.957 | J124: 584.71718 | K124: 1.1218364 | L124: 0.903 | M124: 2.07 | N124: 0.52 | O124: 0.295 | P124: 0.171 | Q124: 0.3 | R124: 0.281 | S124: 0.055 | T124: 0.1
... A128: 42401 | B128: 1271 | C128: 640 | D128: 377.38 | E128: 159.67661 | F128: 115 | G128: 33.2 | H128: 727.65 | I128: 655.957 | J128: 590.74951 | K128: 1.110381 | L128: 0.592 | M128: 1.78 | N128: 0.17 | O128: -0.065 | P128: 1.02 | Q128: 0.3 | R128: 0 | S128: -0.19 | T128: -0.2
A129: 42430 | B129: 1286 | C129: 686 | D129: 374.9 | E129: 159.13727 | F129: 115 | G129: 39.07 | H129: 824.47 | I129: 655.957 | J129: 588.81885 | K129: 1.1140217 | L129: 0.509 | M129: 1.890 | N129: 0.17 | O129: -0.05 | P129: 0.85 | Q129: -0.1 | R129: 0.28 | S129: -0.15 | T129: 0
A130: 42461 | B130: 1350 | C130: 723 | D130: 383.53 | E130: 164.41258 | F130: 115 | G130: 42.25 | H130: 814.98 | I130: 655.957 | J130: 578.50606 | K130: 1.133881 | L130: 0.514 | M130: 1.81 | N130: 0.13 | O130: -0.085 | P130: 1.125 | Q130: -0.3 | R130: -0.09 | S130: -0.19 | T130: -0.2
A131: 42491 | B131: 1600 | C131: 706.25 | D131: 414.38 | E131: 168.96 | F131: 115 | G131: 47.13 | H131: 818.25 | I131: 655.957 | J131: 579.93 | K131: 1.1297455 | L131: 0.509 | M131: 1.81 | N131: 0.13 | O131: -0.12 | P131: 1.022 | Q131: -0.4 | R131: 0.093 | S131: -0.02 | T131: -0.1
A132: 42522 | B132: 1700 | C132: 683 | D132: 426.83 | E132: 179.87239 | F132: 115 | G132: 48.48 | H132: 822.38 | I132: 655.957 | J132: 583.98605 | K132: 1.1232409 | L132: 0.39 | M132: 1.64 | N132: -0.02 | O132: -0.235 | P132: 1.006 | Q132: -0.4 | R132: 0.28 | S132: 0.189 | T132: 0.1
A133: 42552 | B133: 1673 | C133: 651 | D133: 417.89 | E133: 161.75918 | F133: 115 | G133: 45.07 | H133: 824.15 | I133: 655.957 | J133: 592.61 | K133: 1.1063476 | L133: 0.175 | M133: 1.5 | N133: -0.15 | O133: -0.18 | P133: 0.84 | Q133: -0.4 | R133: 0.37 | S133: 0.22 | T133: 0.2
...

Sheet Primaire
A1: DIRECTION DE LA PREVISION ET DES ETUDES ECONOMIQUES
B2: =B247/B246-1 -> -0.14275371 | C2: =C247/C246-1 -> 0.10355542 | D2: =D247/D246-1 -> 0.34326579 | E2: =E247/E246-1 -> 0.075940306
B3: DONNEES DE PRODUCTION | H3: INDICE PRIMAIRE (base 100=2022)
B4: Abattages contrôlés de viande | C4: Pêche | I4: Elevage | J4: Pêche
D5: Industrielle | E5: Artisanale | K5: Artisanale | L5: Industrielle
B6: (tonnes) | C6: (tonnes) | D6: (tonnes) | E6: (tonnes)
A7: 38718 | B7: 940.988 | C7: =SUM(D7:E7) -> 33253 | D7: 4588 | E7: 28665 | AT7: 4.236331 | AU7: 1.737522 | AV7: =AU7+AT7 -> 5.9738529
A8: 38749 | B8: 1341.832 | C8: =SUM(D8:E8) -> 35111 | D8: 3984 | E8: 31127
A9: 38777 | B9: 1567.5 | C9: =SUM(D9:E9) -> 33232 | D9: 5082 | E9: 28150
A10: 38808 | B10: 1539.888 | C10: =SUM(D10:E10) -> 36126 | D10: 6457 | E10: 29669
A11: 38838 | B11: 1495.521 | C11: =SUM(D11:E11) -> 42645 | D11: 5456 | E11: 37189
A12: 38869 | B12: 1534.648 | C12: =SUM(D12:E12) -> 42039 | D12: 4763 | E12: 37276
A13: 38899 | B13: 1582.879 | C13: =SUM(D13:E13) -> 32359 | D13: 5183 | E13: 27176
A14: 38930 | B14: 1588.552 | C14: =SUM(D14:E14) -> 29389 | D14: 5890 | E14: 23499
A15: 38961 | B15: 1626.623 | C15: =SUM(D15:E15) -> 24505 | D15: 5152 | E15: 19353
A16: 38991 | B16: 1616.261 | C16: =SUM(D16:E16) -> 20708 | D16: 2839 | E16: 17869
A17: 39022 | B17: 1650.716 | C17: =SUM(D17:E17) -> 29200 | D17: 5107 | E17: 24093
A18: 39052 | B18: 1658.469 | C18: =SUM(D18:E18) -> 35333 | D18: 5137 | E18: 30196
A19: 39083 | B19: 1223.853 | C19: =SUM(D19:E19) -> 33198.06 | D19: 5348 | E19: 27850.06
... A126: 42339 | B126: 2167.2815 | C126: =SUM(D126:E126) -> 43475.383 | D126: 8634 | E126: 34841.383
A127: 42370 | B127: 2005.7405 | C127: =SUM(D127:E127) -> 51260.865 | D127: 7769 | E127: 43491.865 | H127: 314.8191 | I127: 359.59173 | J127: 117.67114 | K127: 158.28663 | L127: 48.296155
A128: 42401 | B128: 1959.4325 | C128: =SUM(D128:E128) -> 46597.958 | D128: 8292 | E128: 38305.958 | H128: 306.07246 | I128: 351.28957 | J128: 106.96727 | K128: 139.41277 | L128: 51.547396
A129: 42430 | B129: 2006.2735 | C129: =SUM(D129:E129) -> 43567.95 | D129: 10126 | E129: 33441.95 | H129: 311.62873 | I129: 359.68728 | J129: 100.01178 | K129: 121.71043 | L129: 62.948496
A130: 42461 | B130: 1990.6305 | C130: =SUM(D130:E130) -> 40977.19 | D130: 9141 | E130: 31836.19 | H130: 308.24261 | I130: 356.88279 | J130: 94.064601 | K130: 115.86634 | L130: 56.825222
A131: 42491 | B131: 2008.153 | C131: =SUM(D131:E131) -> 67693.51 | D131: 13032 | E131: 54661.51 | H131: 322.15279 | I131: 360.02424 | J131: 155.39287 | K131: 198.93804 | L131: 81.013707
A132: 42522 | B132: 1761.4615 | C132: =SUM(D132:E132) -> 57379.01 | D132: 10672 | E132: 46707.01 | H132: 281.72882 | I132: 315.79707 | J132: 131.71556 | K132: 169.98801 | L132: 66.342717
A133: 42552 | B133: 2061.3285 | C133: =SUM(D133:E133) -> 38606.548 | D133: 8433 | E133: 30173.548 | H133: 317.56455 | I133: 369.55761 | J133: 88.622708 | K133: 109.81523 | L133: 52.423925
A134: 42583 | B134: 2028.184 | C134: =SUM(D134:E134) -> 37751.408 | D134: 7325 | E134: 30426.408 | H134: 312.35879 | I134: 363.61543 | J134: 86.659704 | K134: 110.73551 | L134: 45.53602
A135: 42614 | B135: 1313.6615 | C135: =SUM(D135:E135) -> 25400.661 | D135: 7901 | E135: 17499.661 | H135: 202.71898 | I135: 235.51492 | J135: 58.308124 | K135: 63.68921 | L135: 49.116736
A136: 42644 | B136: 1805.072 | C136: =SUM(D136:E136) -> 26813.653 | D136: 7691 | E136: 19122.653 | H136: 275.11504 | I136: 323.61562 | J136: 61.551697 | K136: 69.596013 | L136: 47.811266
A137: 42675 | B137: 1843.7445 | C137: =SUM(D137:E137) -> 29282.293 | D137: 6497 | E137: 22785.293 | H137: 281.81392 | I137: 330.54888 | J137: 67.218548 | K137: 82.926022 | L137: 40.38874
A138: 42705 | B138: 2249.9145 | C138: =SUM(D138:E138) -> 37180.2 | D138: 7761 | E138: 29419.2 | H138: 344.51126 | I138: 403.36755 | J138: 85.348475 | K138: 107.06982 | L138: 48.246423
... A247: 46023 | B247: 2334.832 | C247: =SUM(D247:E247) -> 44814.612 | D247: 5635 | E247: 39179.612 | H247: 110.09631 | I247: 111.73661 | J247: 102.87354 | K247: 142.59239 | L247: 35.030098

Sheet Secteur Secondaire
A1: DIRECTION DE LA PREVISION ET DES ETUDES ECONOMIQUES
B3: =B247/B246-1 -> -0.0027715639 | C3: =C247/C246-1 -> -0.061808271 | D3: =D247/D246-1 -> -0.034246575 | E3: =E247/E246-1 -> -0.42649991 | F3: =F247/F246-1 -> 0.79262082 | G3: =G247/G246-1 -> 0.98505549 | H3: =H247/H246-1 -> -0.456704 | I3: =I247/I246-1 -> 1.1414931 | ... Y3: =Y247/Y246-1 -> 0.96556004
B4: PETROLE BRUT (PRODUCTION) | C4: Phosphates (PRODUCTION) | F4: Produits arachidiers (PRODUCTION) | J4: OR (PRODUCTION) | K4: Ventes d'électricité | P4: EAU | R4: CIMENT | U4: Produits chimiques (PRODUCTION) | W4: SEL | Z4: COTON
D5: phos. de calcium | E5: attapulgite | G5: huile brute | H5: huile raffinée | I5: tourteaux | L5: basse tension | M5: moyenne tension | N5: haute tension | O5: Exportations | P5: Production | Q5: Ventes | R5: Production | S5: Ventes locales | T5: Exportations | U5: Acide phosphorique | V5: Engrais solides | W5: Production | X5: Ventes locales | Y5: Exportations | Z5: Production | AA5: Ventes locales | AB5: Exportations
B6: (millions bbl) | C6: (1000 tonnes) | D6: (1000 tonnes) | E6: (1000 tonnes) | F6: (1000 tonnes) | G6: (1000 tonnes) | H6: (1000 tonnes) | I6: (1000 tonnes) | J6: (Kilogramme) | K6: (millions kwh) | L6: (millions kwh) | M6: (millions kwh) | N6: (millions kwh) | O6: (millions kwh) | P6: (millions m3) | Q6: (millions m3) | R6: (1000 tonnes) | S6: (1000 tonnes) | T6: (1000 tonnes) | U6: (1000 tonnes) | V6: (1000 tonnes) | W6: (tonnes) | X6: (tonnes) | Y6: (tonnes) | Z6: (tonnes) | AA6: (tonnes) | AB6: (tonnes)
A7: 38718 | C7: =D7+E7 -> 132.542 | D7: 119 | E7: 13.542 | F7: =G7+H7+I7 -> 5.156 | G7: 0 | H7: 5.156 | I7: 0 | K7: =SUM(L7:O7) -> 133.526 | L7: 87.019 | M7: 30 | N7: 16.507 | P7: 11.341169 | R7: =137.655+93.5461 -> 231.2011 | S7: =108.537+8.1739 -> 116.7109 | T7: =22.387+86.218 -> 108.605 | U7: 41.703 | V7: 1.87 | W7: 15493.7 | X7: 2074 | Y7: 13419 | Z7: 6266 | AA7: 58.2 | AB7: 395.9
A8: 38749 | C8: =D8+E8 -> 114.942 | D8: 100 | E8: 14.942 | F8: =G8+H8+I8 -> 8.568 | G8: 1.207 | H8: 6.019 | I8: 1.342 | K8: =SUM(L8:O8) -> 133.704 | L8: 82.717 | M8: 35.841 | N8: 15.146 | P8: 9.862406 | Q8: 16.808839 | R8: =92.2153+139.647 -> 231.8623 | S8: =57.2813+122.808 -> 180.0893 | T8: =37.0077+20.967 -> 57.9747 | U8: 26.695 | V8: 2.696 | W8: 16811 | X8: 2358 | Y8: 14453 | Z8: 5108 | AA8: 83.2 | AB8: 1560.4
A9: 38777 | C9: =D9+E9 -> 11.289 | D9: 0 | E9: 11.289 | F9: =G9+H9+I9 -> 22.755 | G9: 6.812 | H9: 7.425 | I9: 8.518 | K9: =SUM(L9:O9) -> 128.638 | L9: 79.245 | M9: 37.511 | N9: 11.882 | P9: 10.804051 | R9: =158.755+101.2842 -> 260.0392 | S9: =138.406+63.1343 -> 201.5403 | T9: =22.278+39.5518 -> 61.8298 | U9: 4.785 | V9: 2.784 | W9: 18405 | X9: 1919 | Y9: 16486 | Z9: 4680.3 | AA9: 55.5 | AB9: 4007
A10: 38808 | C10: =D10+E10 -> 9.451 | D10: 0 | E10: 9.451 | F10: =G10+H10+I10 -> 20.073 | G10: 5.009 | H10: 9.301 | I10: 5.763 | K10: =SUM(L10:O10) -> 118.925 | L10: 72.599 | M10: 35.183 | N10: 11.143 | P10: 10.769033 | Q10: 17.236263 | R10: =181.964+93.2032 -> 275.1672 | S10: =144.703+54.6277 -> 199.3307 | T10: =36.068+35.1807 -> 71.2487 | U10: 0 | V10: 2.093 | W10: 16801 | X10: 2197 | Y10: 14604 | Z10: 391.2 | AA10: 80.2 | AB10: 2400
A11: 38838 | C11: =D11+E11 -> 131.588 | D11: 121 | E11: 10.588 | F11: =G11+H11+I11 -> 19.989 | G11: 6.044 | H11: 8.346 | I11: 5.599 | K11: =SUM(L11:O11) -> 132.01 | L11: 76.559 | M11: 38.107 | N11: 17.344 | P11: 11.198387 | R11: =191.072+101.9546 -> 293.0266 | S11: =155.942+66.2339 -> 222.1759 | T11: =39.7+37.5798 -> 77.2798 | U11: 13.224 | V11: 2.845 | W11: 20128 | X11: 2368 | Y11: 17760 | Z11: 0 | AA11: 117.9 | AB11: 707.4
A12: 38869 | C12: =D12+E12 -> 64.229 | D12: 50 | E12: 14.229 | F12: =G12+H12+I12 -> 20.387 | G12: 7.076 | H12: 9.823 | I12: 3.488 | K12: =SUM(L12:O12) -> 134.494 | L12: 80.36 | M12: 41.105 | N12: 13.029 | P12: 11.056102 | Q12: 17.920596 | R12: =155.758+98.5608 -> 254.3188 | S12: =131.296+61.2307 -> 192.5267 | T12: =35.2253+29.515 -> 64.7403 | U12: 12.931 | V12: 3.521 | W12: 12726 | X12: 1910 | Y12: 10816 | Z12: 0 | AA12: 107.2 | AB12: 852.8
A13: 38899 | C13: =D13+E13 -> 12.347 | D13: 0 | E13: 12.347 | F13: =G13+H13+I13 -> 24.276 | G13: 6.41 | H13: 6.707 | I13: 11.159 | K13: =SUM(L13:O13) -> 147.465 | L13: 92.05 | M13: 45.098 | N13: 10.317 | P13: 11.135407 | R13: =101.2427+133.271 -> 234.5137 | S13: =108.666+69.7141 -> 178.3801 | T13: =31.9995+19.075 -> 51.0745 | U13: 0 | V13: 4.729 | W13: 17157 | X13: 1982 | Y13: 15175 | Z13: 0 | AA13: 73.1 | AB13: 1259.3
A14: 38930 | C14: =D14+E14 -> 16.741 | D14: 0 | E14: 16.741 | F14: =G14+H14+I14 -> 20.746 | G14: 5.121 | H14: 7.738 | I14: 7.887 | K14: =SUM(L14:O14) -> 147.493 | L14: 92.461 | M14: 46.028 | N14: 9.004 | P14: 10.48293 | Q14: 17.207542 | R14: =142.314+103.9511 -> 246.2651 | S14: =69.5017+127.057 -> 196.5587 | T14: =22.557+36.5121 -> 59.0691 | U14: 0 | V14: 1.684 | W14: 15808 | X14: 2365 | Y14: 13443 | Z14: 0 | AA14: 64.1 | AB14: 1786
A15: 38961 | C15: =D15+E15 -> 10.504 | D15: 0 | E15: 10.504 | F15: =G15+H15+I15 -> 14.972 | G15: 2.996 | H15: 7.182 | I15: 4.794 | K15: =SUM(L15:O15) -> 155.872 | L15: 102.654 | M15: 44.465 | N15: 8.753 | P15: 10.101425 | R15: =121.382+96.091 -> 217.473 | S15: =97.367+56.7947 -> 154.1617 | T15: =27.081+34.6539 -> 61.7349 | U15: 2.314 | V15: 0 | W15: 13745 | X15: 2173 | Y15: 11572 | Z15: 0 | AA15: 43.7 | AB15: 2871.2
A16: 38991 | C16: =D16+E16 -> 58.115 | D16: 51 | E16: 7.115 | F16: =G16+H16+I16 -> 24.362 | G16: 7.541 | H16: 8.185 | I16: 8.636 | K16: =SUM(L16:O16) -> 151.564 | L16: 96.131 | M16: 42.321 | N16: 13.112 | P16: 10.731093 | Q16: 17.008616 | R16: =76.5177+123.391 -> 199.9087 | S16: =42.5112+93.823 -> 136.3342 | T16: =29.8152+25.673 -> 55.4882 | U16: 28.573 | V16: 0 | W16: 14813 | X16: 2146 | Y16: 12667 | Z16: 0 | AA16: 51.2 | AB16: 1869.6
A17: 39022 | C17: =D17+E17 -> 76.583 | D17: 66 | E17: 10.583 | F17: =G17+H17+I17 -> 30.188 | G17: 9.153 | H17: 9.995 | I17: 11.04 | K17: =SUM(L17:O17) -> 160.998 | L17: 101.109 | M17: 45.17 | N17: 14.719 | P17: 10.936115 | R17: =138.824+85.3385 -> 224.1625 | S17: =107.496+55.3475 -> 162.8435 | T17: =39.0071+34.847 -> 73.8541 | U17: 28.527 | V17: 4.647 | W17: 14847 | X17: 2719 | Y17: 12128 | Z17: 0 | AA17: 59 | AB17: 956
A18: 39052 | C18: =D18+E18 -> 96.991 | D18: 77 | E18: 19.991 | F18: =G18+H18+I18 -> 22.988 | G18: 6.133 | H18: 8.859 | I18: 7.996 | K18: =SUM(L18:O18) -> 166.912 | L18: 103.716 | M18: 46.473 | N18: 16.723 | P18: 11.041675 | Q18: 17.49626 | R18: =95.969+169.875 -> 265.844 | S18: =57.381+133.29 -> 190.671 | T18: =30.563+38.1869 -> 68.7499 | U18: 21.608 | V18: 6.564 | W18: 21826 | X18: 2637 | Y18: 19189 | Z18: 2522 | AA18: 15 | AB18: 253.6
A19: 39083 | C19: =D19+E19 -> 82.152 | D19: 72 | E19: 10.152 | F19: =G19+H19+I19 -> 15.027 | G19: 4.239 | H19: 5.358 | I19: 5.43 | K19: =SUM(L19:O19) -> 120.104 | L19: 88.675 | M19: 14.778 | N19: 16.651 | P19: 11.695173 | R19: =155.983+94.8327 -> 250.8157 | S19: =131.307+60.4849 -> 191.7919 | T19: =36.473+25.764 -> 62.237 | U19: 20.348 | V19: 7.406 | W19: 14074 | X19: 2823 | Y19: 11251 | Z19: 7499.5 | AA19: 1.6 | AB19: 597.5
A20: 39114 | C20: =D20+E20 -> 70.25 | D20: 60 | E20: 10.25 | F20: =G20+H20+I20 -> 24.973 | G20: 6.652 | H20: 12.13 | I20: 6.191 | K20: =SUM(L20:O20) -> 133.348 | L20: 83.925 | M20: 36.871 | N20: 12.552 | P20: 10.417437 | Q20: 17.202009 | R20: =148.808+89.7297 -> 238.5377 | S20: =119.112+54.175 -> 173.287 | T20: =28.083+35.1925 -> 63.2755 | U20: 14.286 | V20: 0 | W20: 19005 | X20: 2710 | Y20: 16295 | Z20: 5222 | AA20: 20 | AB20: 778.2
A21: 39142 | C21: =D21+E21 -> 56.874 | D21: 50 | E21: 6.874 | F21: =G21+H21+I21 -> 25.197 | G21: 7.399 | H21: =8.998+0.16 -> 9.158 | I21: 8.64 | K21: =SUM(L21:O21) -> 133.085 | L21: 84.183 | M21: 40.008 | N21: 8.894 | P21: 11.688113 | R21: =137.341+99.612 -> 236.953 | S21: =115.718+67.0727 -> 182.7907 | T21: =23.827+33.3453 -> 57.1723 | U21: 22.349 | V21: 5.666 | W21: 21544 | X21: 2673 | Y21: 18871 | Z21: 13491.2 | AA21: 48 | AB21: 2066.2
A22: 39173 | C22: =D22+E22 -> 105.301 | D22: 96 | E22: 9.301 | F22: =G22+H22+I22 -> 23.675 | G22: 8.697 | H22: =3.673+0.345 -> 4.018 | I22: 10.96 | K22: =SUM(L22:O22) -> 130.345 | L22: 80.783 | M22: 40.422 | N22: 9.14 | P22: 11.202731 | Q22: 17.968486 | R22: =174.258+96.9052 -> 271.1632 | S22: =137.188+59.3145 -> 196.5025 | T22: =33.404+31.0476 -> 64.4516 | U22: 26.493 | V22: 5.754 | W22: 14575 | X22: 2738 | Y22: 11837 | Z22: 8282 | AA22: 39.5 | AB22: 239.7
A23: 39203 | C23: =D23+E23 -> 80.725 | D23: 70.3 | E23: 10.425 | F23: =G23+H23+I23 -> 24.241 | G23: 8.156 | H23: 6.824 | I23: 9.261 | K23: =SUM(L23:O23) -> 140.557 | L23: 88.816 | M23: 42.606 | N23: 9.135 | P23: 11.712704 | R23: =90.3906+161.549 -> 251.9396 | S23: =61.0006+134.069 -> 195.0696 | T23: =30.5479+30.586 -> 61.1339 | U23: 29.079 | V23: 10.96 | W23: 17231 | X23: 3252 | Y23: 13979 | Z23: 0 | AA23: 34 | AB23: 1579.4
A24: 39234 | C24: =D24+E24 -> 70.423 | D24: 56 | E24: 14.423 | F24: =G24+H24+I24 -> 21.025 | G24: 7.684 | H24: =3.306+0.185 -> 3.491 | I24: 9.85 | K24: =SUM(L24:O24) -> 135.758 | L24: 86.17 | M24: 40.428 | N24: 9.16 | P24: 11.351162 | Q24: 18.061358 | R24: =174.751+66.7315 -> 241.4825 | S24: =146.719+49.4817 -> 196.2007 | T24: =22.657+26.26 -> 48.917 | U24: 17.162 | V24: 12.513 | W24: 18468 | X24: 2094 | Y24: 16374 | Z24: 0 | AA24: 20.6 | AB24: 2740.5
A25: 39264 | C25: =D25+E25 -> 85.507 | D25: 73 | E25: 12.507 | F25: =G25+H25+I25 -> 11.048 | G25: 0.025 | H25: 9.359 | I25: 1.664 | K25: =SUM(L25:O25) -> 143.568 | L25: 88.297 | M25: 44.522 | N25: 10.749 | P25: 11.366838 | R25: =174.364+91.2834 -> 265.6474 | S25: =149.177+60.299 -> 209.476 | T25: =27.476+27.0548 -> 54.5308 | U25: 17.932 | V25: 8.84 | W25: 15908 | X25: 2615.8 | Y25: 13292 | Z25: 0 | AA25: 6 | AB25: 2811.4
A26: 39295 | C26: =D26+E26 -> 62.124 | D26: 51 | E26: 11.124 | F26: =G26+H26+I26 -> 12.348 | G26: 2.077 | H26: =8.766+0.101 -> 8.867 | I26: 1.404 | K26: =SUM(L26:O26) -> 151.284 | L26: 97.939 | M26: 44.026 | N26: 9.319 | P26: 10.928509 | Q26: 17.840605 | R26: =101.15234+177.67 -> 278.82234 | S26: =0.25+65.84362+137.1 -> 203.19362 | T26: =0.385+36.89185+33.5 -> 70.77685 | U26: 15.966 | V26: 7.245 | W26: =(W25+W24)/2 -> 17188 | X26: =(X25+X24)/2 -> 2354.9 | Y26: =(Y25+Y24)/2 -> 14833 | Z26: 0 | AA26: 15.3 | AB26: 219.8
A27: 39326 | C27: =D27+E27 -> 57.363 | D27: 47 | E27: 10.363 | F27: =G27+H27+I27 -> 8.343 | G27: 0 | H27: 7.582 | I27: 0.761 | K27: =SUM(L27:O27) -> 154.158 | L27: 99.644 | M27: 45.519 | N27: 8.995 | P27: 10.645413 | R27: =159.362+92.461 -> 251.823 | S27: =131.924+48.452 -> 180.376 | T27: =25.472+34.3461 -> 59.8181 | U27: 15.471 | V27: 4.105 | W27: 17401 | X27: 2390 | Y27: 15011 | Z27: 0 | AA27: 0.2 | AB27: 3.5
A28: 39356 | C28: =D28+E28 -> 57.188 | D28: 44 | E28: 13.188 | F28: =G28+H28+I28 -> 8.262 | G28: 0 | H28: =7.767+0.201 -> 7.968 | I28: 0.294 | K28: =SUM(L28:O28) -> 164.704 | L28: 107.103 | M28: 47.781 | N28: 9.82 | P28: 11.404618 | Q28: 18.499164 | R28: =150.6+82.3423 -> 232.9423 | S28: =121.9+48.2346 -> 170.1346 | T28: =28.7+37.8169 -> 66.5169 | U28: 15.156 | V28: 4.997 | W28: 18133 | X28: 2537 | Y28: 15596 | Z28: 0 | AA28: 20.3 | AB28: 3491.2
A29: 39387 | C29: =D29+E29 -> 67.506 | D29: 60 | E29: 7.506 | F29: =G29+H29+I29 -> 8.192 | G29: 0 | H29: 8.192 | I29: 0 | K29: =SUM(L29:O29) -> 167.609 | L29: 110.664 | M29: 46.967 | N29: 9.978 | P29: 11.499036 | R29: =167.813+97.7169 -> 265.5299 | S29: =140.914+50.7265 -> 191.6405 | T29: =30.76+51.3545 -> 82.1145 | U29: 19.749 | V29: 4.526 | W29: 20217 | X29: 2404 | Y29: 17813 | Z29: 0 | AA29: 5.7 | AB29: 661.2
A30: 39417 | C30: =D30+E30 -> 56.391 | D30: 38.9 | E30: 17.491 | F30: =G30+H30+I30 -> 9.285 | G30: 0 | H30: 9.285 | I30: 0 | K30: =SUM(L30:O30) -> 163.826 | L30: 108.824 | M30: 47.555 | N30: 7.447 | P30: 11.700825 | Q30: 18.59971 | R30: =162.687+1.32506+90.37428+0.03+0.50275 -> 254.91909 | S30: =125.125+44.72418+0.9084+0.71786 -> 171.47544 | T30: =35.141+0.485+42.51735+0.03 -> 78.17335 | U30: 20.137 | V30: 10.222 | W30: 17225 | X30: 2100 | Y30: 15125 | Z30: 1203.23 | AA30: 19.053 | AB30: 220
A31: 39448 | C31: =D31+E31 -> 68.349 | D31: 55 | E31: 13.349 | F31: =G31+H31+I31 -> 14.356 | G31: 3.585 | H31: =8.581+0.144 -> 8.725 | I31: 2.046 | K31: =SUM(L31:O31) -> 158.829 | L31: 101.575 | M31: 48.439 | N31: 8.815 | P31: 12.499291 | Q31: 9.9527397 | R31: =161.108+102.9307 -> 264.0387 | S31: =139.412+0.59965+58.53935+1.95952 -> 200.51052 | T31: =31.778+1.53+42.4453+0.04 -> 75.7933 | U31: 16.039 | V31: 3.42 | W31: 25053 | X31: 3603 | Y31: 19742.1 | Z31: 5385.1 | AA31: 16.1 | AB31: 1628.8
A32: 39479 | C32: =D32+E32 -> 74.042 | D32: 54 | E32: 20.042 | F32: =G32+H32+I32 -> 19.913 | G32: 4.727 | H32: =8.462+0 -> 8.462 | I32: 6.724 | K32: =SUM(L32:O32) -> 134.796 | L32: 91.941 | M32: 34.307 | N32: 8.548 | P32: 11.232945 | Q32: 8.9511401 | R32: =98.5763+167.819 -> 266.3953 | S32: =134.877+1.4052+55.00282+1.70105 -> 192.98607 | T32: =25.186+1.034+39.6577+0.08 -> 65.9577 | U32: 16.679 | V32: 5.397 | W32: 22370 | X32: 2997 | Y32: 22370 | Z32: 4333.2 | AA32: 14.7 | AB32: 1494.2
A33: 39508 | C33: =D33+E33 -> 57.504 | D33: 40 | E33: 17.504 | F33: =G33+H33+I33 -> 9.946 | G33: 0.332 | H33: =7.533+0.189 -> 7.722 | I33: 1.892 | K33: =SUM(L33:O33) -> 141.615 | L33: 86.809 | M33: 46.551 | N33: 8.255 | P33: 11.781936 | Q33: 9.1682036 | R33: =147.283+1.61572+97.34844+0.7994 -> 247.04656 | S33: =133.368+1.58002+55.77642+0.764 -> 191.48844 | T33: =13.197+0.046+37.2446+0.03 -> 50.5176 | U33: 14.779 | V33: 0 | W33: 19361 | X33: 2994 | Y33: 16367 | Z33: 3930.7 | AA33: 9.3 | AB33: 1622.3
A34: 39539 | C34: =D34+E34 -> 54.361 | D34: 44 | E34: 10.361 | F34: =G34+H34+I34 -> 11.547 | G34: 2.915 | H34: 4.367 | I34: 4.265 | K34: =SUM(L34:O34) -> 151.661 | L34: 100.04 | M34: 43.069 | N34: 8.552 | P34: 11.569475 | Q34: 9.2571065 | R34: =168.527+102.2512 -> 270.7782 | S34: =68.3068+152.295 -> 220.6018 | T34: =38.0999+22.471 -> 60.5709 | U34: 8.967 | V34: 7.358 | W34: 24009 | X34: 3323 | Y34: 20686 | Z34: 593 | AA34: 18.8 | AB34: 1718.3
A35: 39569 | C35: =D35+E35 -> 51.063 | D35: 38 | E35: 13.063 | F35: =G35+H35+I35 -> 7.114 | G35: 0 | H35: 6.922 | I35: 0.192 | K35: =SUM(L35:O35) -> 158.734 | L35: 104.725 | M35: 46.217 | N35: 7.792 | P35: 12.085955 | Q35: 9.7079807 | R35: =101.4756+174.557 -> 276.0326 | S35: =149.11+66.5737 -> 215.6837 | T35: =24.974+36.6496 -> 61.6236 | U35: 17.969 | V35: 12.178 | W35: 19698 | X35: 2565 | Y35: 17133 | Z35: 0 | AA35: 12.1 | AB35: 1508.7
A36: 39600 | C36: =D36+E36 -> 53.126 | D36: 37 | E36: 16.126 | F36: =G36+H36+I36 -> 3.149 | G36: 0 | H36: 3.075 | I36: 0.074 | K36: =SUM(L36:O36) -> 152.999 | L36: 99.329 | M36: 45.362 | N36: 8.308 | P36: 11.157268 | Q36: 8.9484204 | R36: =179.232+98.9123 -> 278.1443 | S36: =61.7947+143.044 -> 204.8387 | T36: =33.184+35.3751 -> 68.5591 | U36: 12.199 | V36: 13.232 | W36: 18669 | X36: 2988 | Y36: 15681 | Z36: 0 | AA36: 19.5 | AB36: 2010
A37: 39630 | C37: =D37+E37 -> 60.766 | D37: 51 | E37: 9.766 | F37: =G37+H37+I37 -> 5.134 | G37: 0 | H37: 5.134 | I37: 0 | K37: =SUM(L37:O37) -> 150.915 | L37: 94.252 | M37: 48.046 | N37: 8.617 | P37: 11.699402 | Q37: 9.2218857 | R37: =179.242+2.35648+95.9806+0.59861 -> 278.17769 | S37: =1.03648+61.26147+0.66+144.331 -> 207.28895 | T37: =37.387+1.32+36.4715 -> 75.1785 | U37: 19.338 | V37: 9.088 | W37: 19641 | X37: 3124 | Y37: 16517 | Z37: 0 | AA37: 17.4 | AB37: 1274
A38: 39661 | C38: =D38+E38 -> 50.223 | D38: 41 | E38: 9.223 | F38: =G38+H38+I38 -> 8.865 | G38: 0.736 | H38: 7.235 | I38: 0.894 | K38: =SUM(L38:O38) -> 165.378 | L38: 111.31 | M38: 46.67 | N38: 7.398 | P38: 10.993662 | Q38: 8.7721994 | R38: =168.846+86.4564 -> 255.3024 | S38: =43.2254+132.106 -> 175.3314 | T38: =40.4126+33.631 -> 74.0436 | U38: 13.665 | V38: 0 | W38: 14569 | X38: 2537 | Y38: 12032 | Z38: 0 | AA38: 9.5 | AB38: 1691
A39: 39692 | C39: =D39+E39 -> 47.848 | D39: 35 | E39: 12.848 | F39: =G39+H39+I39 -> 8.55 | G39: 1.119 | H39: 5.97 | I39: 1.461 | K39: =SUM(L39:O39) -> 156.474 | L39: 102.276 | M39: 46.731 | N39: 7.467 | P39: 10.878314 | Q39: 8.6263999 | R39: =137.783+1.73113+93.49888+0.015 -> 233.02801 | S39: =0.53659+34.55327+0.01+110.744 -> 145.84386 | T39: =25.509+1.03+56.9197 -> 83.4587 | U39: 13.867 | V39: 0 | W39: 18707 | X39: 3475 | Y39: 15232 | Z39: 0 | AA39: 11.65 | AB39: 722.806
A40: 39722 | C40: =D40+E40 -> 50.08 | D40: 43 | E40: =5.91+1.17 -> 7.08 | F40: =G40+H40+I40 -> 3.632 | G40: 0 | H40: 3.632 | I40: 0 | K40: =SUM(L40:O40) -> 166.646 | L40: 114.442 | M40: 43.411 | N40: 8.793 | P40: 11.669107 | Q40: 9.3158463 | R40: =91.7503+140.798 -> 232.5483 | S40: =121.348+33.7642 -> 155.1122 | T40: =48.8697+21.871 -> 70.7407 | U40: 12.61 | V40: 0 | W40: 17310 | X40: 3074 | Y40: 14236 | Z40: 0 | AA40: 12.747 | AB40: 689.425
A41: 39753 | C41: =D41+E41 -> 72.787 | D41: 50 | E41: =19.66+3.127 -> 22.787 | F41: =G41+H41+I41 -> 8.855 | G41: 0 | H41: 8.855 | I41: 0 | K41: =SUM(L41:O41) -> 164.618 | L41: 110.278 | M41: 46.188 | N41: 8.152 | P41: 11.374741 | Q41: 9.0510946 | R41: =179.8+86.5637 -> 266.3637 | S41: =37.1495+144.388 -> 181.5375 | T41: =46.1088+25.053 -> 71.1618 | U41: 9.477 | V41: 0 | W41: 20424 | X41: 2934 | Y41: 17490 | Z41: 0 | AA41: 0.374 | AB41: 400
...

Sheet Indice Secondaire
A1: DIRECTION DE LA PREVISION ET DES ETUDES ECONOMIQUES
B3: INDICE CHIFFRE D'AFFAIRES DU SECTEUR SECONDAIRE (base 100 = 2022)*
C4: INDUSTRIE | BA4: CONSTRUCTION
D5: ACTIVITES EXTRACTIVES | J5: FABRICATION DE PRODUITS AGRO-ALIMENTAIRES | X5: RAFFINAGE PETROLIER ET COKEFACTION | Y5: FABRICATION DE PRODUITS CHIMIQUES DE BASE | Z5: FABRICATION DE CIMENT ET D'AUTRES MATERIAUX DE CONSTRUCTION | AA5: PRODUCTION DE L'EGRENAGE DU COTON | AB5: PRODUCTION DE LA FILATURE, DU TISSAGE ET DE L'ENNOBLISSEMENT TEXTILE | AC5: TRAVAIL DU CUIR; FABRICATION D'ARTICLES DE VOYAGE ET DE CHAUSSURES | AD5: SCIAGE ET RABOTAGE DU BOIS | AE5: FABRICATION DE PAPIER CARTON ET D'ARTICLES EN PAPIER OU CARTON | AF5: FABRICATION DE PRODUITS PHARMACEUTIQUES | AG5: FABRICATION DE SAVONS, DETERGENTS ET PRODUITS D'ENTRETIEN | AH5: TRAVAIL DU CAOUTCHOUC ET DU PLASTIQUE | AI5: PRODUCTION DE METALLURGIE ET DE FONDERIE; FABRICATION D'OUVRAGES EN METAUX | AJ5: FABRICATION DE MATERIELS DE TRANSPORT | AM5: AUTRES INDUSTRIES MANUFACTURIERES | AW5: Production et distribution d'électricité et de supports énergétiques | AX5: PRODUCTION ET DISTRIBUTION D'EAU, ASSAINISSEMENT ET TRAITEMENT DES DECHETS | BB5: Génie civil | BC5: Activités spécialisées de construction | BD5: Construction de bâtiments et travaux de construction
E6: Extraction de phosphates naturels | F6: Extraction de minerais metalliques | G6: Extraction d'hydrocarbure | H6: Autres extractions | I6: Activités de soutien aux industries extractives | K6: Abattage, transformation, et conservation des viandes | L6: Transformation et conservation des poissons, crustacés et mollusques | M6: Fabrication de corps gras alimentaires | N6: Travail des grains | O6: Fabrication d'aliments pour animaux | P6: Fabrication de pain et de pâtisseries | Q6: Fabrication de produits alimentaires à base de céréales n.c.a | R6: Conserves de fruits et légumes | S6: Fabrication de produits laitiers et de glaces alimentaires | T6: Fabrication de sucre, chocolaterie et confiserie | U6: Fabrication d'autres produits alimentaires | V6: Fabrication de boissons | W6: Fabrication de produits à base de tabac | AK6: Construction de véhicules automobiles et composants | AL6: Fabrication d'autres matériels de transports | AN6: Imprimerie et activités annexes | AO6: Fabrication d'autres produits chimiques | AP6: Fabrication de produits électroniques et informatiques | AQ6: Fabrication d'équipements électriques | AR6: Fabrication de machines et matériels divers à usage général | AS6: Fabrication de machines et matériels divers à usage spécifique | AT6: Fabrication de meubles et matelas | AU6: Installation et réparation de machines et d'équipements | AV6: Autres industries manufacturières n.c.a | AY6: Captage, traitement et distribution d'eau | AZ6: Collecte et traitement des eaux usées; récupération des déchets
A7: 42370 | B7: 50.653394 | C7: 42.735981 | D7: 23.031184 | E7: 114.61377 | F7: 12.046074 | G7: 177.88455 | H7: 45.128746 | I7: 47.666892 | J7: 52.925083 | K7: 61.42906 | L7: 75.020525 | M7: 28.399064 | N7: 42.049432 | O7: 40.707747 | P7: 49.326822 | Q7: 92.851958 | R7: 80.701748 | S7: 55.15296 | T7: 52.330197 | U7: 52.152086 | V7: 83.9158 | W7: 130.05415 | X7: 37.095477 | Y7: 25.88567 | Z7: 67.897883 | AA7: 91.161615 | AB7: 83.875446 | AC7: 206.31856 | AD7: 279.36594 | AE7: 97.354264 | AF7: 116.17702 | AG7: 46.16779 | AH7: 95.924191 | AI7: 101.61967 | AJ7: 56.463779 | AK7: 0 | AL7: 0 | AM7: 52.349425 | AN7: 80.082164 | AO7: 34.27414 | AP7: 0 | AQ7: 74.364596 | AR7: 0 | AS7: 71.859081 | AT7: 0 | AU7: 0 | AV7: 75.844539 | AW7: 38.086066 | AX7: 105.15769 | AY7: 108.3982 | AZ7: 82.207084 | BA7: 164.1191 | BB7: 133.17576 | BC7: 142.12691 | BD7: 92.928945
A8: 42401 | B8: 49.54939 | C8: 41.511877 | D8: 22.726044 | E8: 164.82625 | F8: 44.143803 | G8: 278.38618 | H8: 44.530836 | I8: 49.073317 | J8: 52.283217 | K8: 82.936169 | L8: 76.216171 | M8: 31.037584 | N8: 38.269692 | O8: 37.048608 | P8: 47.573667 | Q8: 89.551848 | R8: 84.731268 | S8: 58.562162 | T8: 46.400468 | U8: 64.104472 | V8: 78.499812 | W8: 127.87778 | X8: 33.436865 | Y8: 20.360734 | Z8: 67.547603 | AA8: 221.53925 | AB8: 94.445975 | AC8: 179.81602 | AD8: 294.54411 | AE8: 110.65725 | AF8: 145.28501 | AG8: 57.186378 | AH8: 76.120346 | AI8: 105.64664 | AJ8: 89.920231 | AK8: 0 | AL8: 0 | AM8: 51.100527 | AN8: 89.216153 | AO8: 41.366457 | AP8: 0 | AQ8: 52.223443 | AR8: 0 | AS8: 50.463914 | AT8: 0 | AU8: 0 | AV8: 66.461711 | AW8: 35.902323 | AX8: 104.68518 | AY8: 95.846526 | AZ8: 158.88495 | BA8: 174.25758 | BB8: 148.46272 | BC8: 107.27732 | BD8: 89.906897
A9: 42430 | B9: 56.567739 | C9: 47.881504 | D9: 20.95448 | E9: 314.97477 | F9: 60.850631 | G9: 245.63119 | H9: 41.059523 | I9: 44.338461 | J9: 66.180776 | K9: 63.225369 | L9: 56.328314 | M9: 156.31708 | N9: 52.965329 | O9: 51.275346 | P9: 48.932495 | Q9: 92.109682 | R9: 73.109302 | S9: 49.171454 | T9: 60.930427 | U9: 75.290115 | V9: 73.873006 | W9: 127.53032 | X9: 37.926339 | Y9: 28.980269 | Z9: 77.248388 | AA9: 195.48172 | AB9: 81.175674 | AC9: 301.38566 | AD9: 240.99858 | AE9: 86.515036 | AF9: 131.77975 | AG9: 58.025808 | AH9: 115.01437 | AI9: 96.535353 | AJ9: 66.992904 | AK9: 0 | AL9: 0 | AM9: 63.917647 | AN9: 74.225703 | AO9: 42.599329 | AP9: 0 | AQ9: 50.954356 | AR9: 0 | AS9: 49.237586 | AT9: 0 | AU9: 0 | AV9: 79.530561 | AW9: 35.217584 | AX9: 126.0006 | AY9: 101.84113 | AZ9: 277.58529 | BA9: 175.98853 | BB9: 147.3061 | BC9: 124.60413 | BD9: 100.23749
A10: 42461 | B10: 52.171553 | C10: 43.390014 | D10: 23.729565 | E10: 211.74315 | F10: 20.914933 | G10: 267.24768 | H10: 46.497199 | I10: 51.968227 | J10: 56.720319 | K10: 80.574281 | L10: 60.19236 | M10: 30.43161 | N10: 45.553851 | O10: 44.100349 | P10: 43.911373 | Q10: 82.65801 | R10: 77.918352 | S10: 48.971898 | T10: 61.348074 | U10: 76.108645 | V10: 68.094651 | W10: 128.87576 | X10: 35.68131 | Y10: 15.611629 | Z10: 74.973461 | AA10: 174.17712 | AB10: 82.957309 | AC10: 226.0218 | AD10: 269.77293 | AE10: 91.529712 | AF10: 117.26613 | AG10: 54.543467 | AH10: 80.530438 | AI10: 112.55112 | AJ10: 88.844959 | AK10: 0 | AL10: 0 | AM10: 69.442111 | AN10: 78.667438 | AO10: 39.859148 | AP10: 0 | AQ10: 125.517 | AR10: 0 | AS10: 121.28804 | AT10: 0 | AU10: 0 | AV10: 87.172177 | AW10: 36.774816 | AX10: 96.358407 | AY10: 97.922592 | AZ10: 84.30193 | BA10: 198.41406 | BB10: 168.48151 | BC10: 125.62096 | BD10: 92.53188
A11: 42491 | B11: 57.916839 | C11: 48.116528 | D11: 23.681688 | E11: 258.95473 | F11: 36.596098 | G11: 377.2027 | H11: 46.403385 | I11: 48.312392 | J11: 63.818087 | K11: 72.43834 | L11: 83.434432 | M11: 45.431698 | N11: 55.161238 | O11: 53.40119 | P11: 53.146693 | Q11: 100.04242 | R11: 64.881471 | S11: 30.54648 | T11: 65.206247 | U11: 73.437167 | V11: 78.68367 | W11: 133.45181 | X11: 39.113119 | Y11: 42.076099 | Z11: 71.257181 | AA11: 26.434945 | AB11: 91.224196 | AC11: 210.52132 | AD11: 280.01578 | AE11: 64.569913 | AF11: 136.03515 | AG11: 48.342819 | AH11: 84.905006 | AI11: 118.10466 | AJ11: 66.186237 | AK11: 0 | AL11: 0 | AM11: 88.046613 | AN11: 71.982876 | AO11: 35.749168 | AP11: 0 | AQ11: 47.162674 | AR11: 0 | AS11: 45.573654 | AT11: 0 | AU11: 0 | AV11: 92.273611 | AW11: 36.106812 | AX11: 128.06493 | AY11: 142.95024 | AZ11: 30.256452 | BA11: 222.68798 | BB11: 161.63155 | BC11: 310.69889 | BD11: 101.80526
A12: 42522 | B12: 57.374722 | C12: 47.855974 | D12: 20.357432 | E12: 185.62745 | F12: 50.015206 | G12: 252.59215 | H12: 39.889628 | I12: 45.736319 | J12: 64.578332 | K12: 88.082995 | L12: 99.922015 | M12: 39.691259 | N12: 53.952612 | O12: 52.231128 | P12: 54.984196 | Q12: 103.5013 | R12: 57.858069 | S12: 54.719715 | T12: 71.211335 | U12: 81.418854 | V12: 78.990017 | W12: 116.37319 | X12: 37.486857 | Y12: 31.330072 | Z12: 65.038829 | AA12: 44.017269 | AB12: 91.84789 | AC12: 193.5822 | AD12: 261.1317 | AE12: 105.67153 | AF12: 129.08317 | AG12: 47.699983 | AH12: 83.42998 | AI12: 97.817721 | AJ12: 19.600743 | AK12: 0 | AL12: 0 | AM12: 66.303324 | AN12: 88.479599 | AO12: 38.283336 | AP12: 0 | AQ12: 69.751889 | AR12: 0 | AS12: 67.401787 | AT12: 0 | AU12: 0 | AV12: 106.556 | AW12: 40.659092 | AX12: 190.90121 | AY12: 197.59369 | AZ12: 144.06601 | BA12: 211.70729 | BB12: 180.39414 | BC12: 130.17603 | BD12: 95.988683
A13: 42552 | B13: 61.154547 | C13: 52.068444 | D13: 20.326071 | E13: 228.13144 | F13: 24.857987 | G13: 230.51336 | H13: 39.828179 | I13: 51.141128 | J13: 58.737013 | K13: 72.108435 | L13: 71.356954 | M13: 40.604858 | N13: 50.809217 | O13: 49.188031 | P13: 48.650127 | Q13: 91.578158 | R13: 57.221542 | S13: 47.257566 | T13: 56.183811 | U13: 60.347006 | V13: 79.69644 | W13: 130.43296 | X13: 70.296222 | Y13: 45.379956 | Z13: 61.572103 | AA13: 105.93572 | AB13: 87.397818 | AC13: 157.1599 | AD13: 271.08236 | AE13: 86.461243 | AF13: 140.1491 | AG13: 47.023933 | AH13: 73.641074 | AI13: 149.95102 | AJ13: 31.58176 | AK13: 0 | AL13: 0 | AM13: 80.760742 | AN13: 78.833434 | AO13: 31.961301 | AP13: 0 | AQ13: 36.181542 | AR13: 0 | AS13: 34.962502 | AT13: 0 | AU13: 0 | AV13: 74.687161 | AW13: 40.404411 | AX13: 102.15507 | AY13: 101.06373 | AZ13: 106.93303 | BA13: 175.99031 | BB13: 135.16547 | BC13: 199.64135 | BD13: 80.895635
A14: 42583 | B14: 58.312721 | C14: 49.419815 | D14: 21.355124 | E14: 122.74233 | F14: 34.670553 | G14: 250.76639 | H14: 41.84457 | I14: 48.986625 | J14: 60.99248 | K14: 87.03755 | L14: 64.773058 | M14: 18.612821 | N14: 47.269949 | O14: 45.761691 | P14: 44.916495 | Q14: 84.550034 | R14: 91.780842 | S14: 54.652206 | T14: 67.535832 | U14: 72.33879 | V14: 99.491397 | W14: 132.09337 | X14: 37.737151 | Y14: 26.030556 | Z14: 68.594217 | AA14: 48.521523 | AB14: 77.757932 | AC14: 129.00717 | AD14: 275.01261 | AE14: 95.358031 | AF14: 141.61357 | AG14: 58.313377 | AH14: 199.12611 | AI14: 201.7474 | AJ14: 53.796384 | AK14: 0 | AL14: 0 | AM14: 70.436396 | AN14: 68.84236 | AO14: 41.695148 | AP14: 0 | AQ14: 40.26173 | AR14: 0 | AS14: 38.905219 | AT14: 0 | AU14: 0 | AV14: 103.90642 | AW14: 42.499931 | AX14: 102.55136 | AY14: 112.13824 | AZ14: 39.127261 | BA14: 178.54552 | BB14: 141.07191 | BC14: 178.16698 | BD14: 147.37502
A15: 42614 | B15: 50.847476 | C15: 43.705837 | D15: 19.803298 | E15: 105.31949 | F15: 31.374167 | G15: 200.9284 | H15: 38.803823 | I15: 33.534222 | J15: 58.077081 | K15: 65.318907 | L15: 78.351017 | M15: 24.913278 | N15: 43.889842 | O15: 42.489434 | P15: 49.781481 | Q15: 93.7078 | R15: 76.458305 | S15: 45.526916 | T15: 62.479789 | U15: 73.69105 | V15: 90.72423 | W15: 141.75793 | X15: 36.77316 | Y15: 37.438392 | Z15: 50.35335 | AA15: 2.0605831 | AB15: 84.428744 | AC15: 248.04577 | AD15: 218.46417 | AE15: 81.628181 | AF15: 159.2184 | AG15: 46.721104 | AH15: 36.304329 | AI15: 72.760779 | AJ15: 97.280124 | AK15: 0 | AL15: 0 | AM15: 73.236424 | AN15: 117.65167 | AO15: 33.786337 | AP15: 0 | AQ15: 34.237286 | AR15: 0 | AS15: 33.083752 | AT15: 0 | AU15: 0 | AV15: 98.038192 | AW15: 39.586998 | AX15: 143.37484 | AY15: 149.31547 | AZ15: 102.3607 | BA15: 126.96984 | BB15: 100.48454 | BC15: 125.69044 | BD15: 93.992769
A16: 42644 | B16: 51.058351 | C16: 43.183142 | D16: 22.827414 | E16: 136.82689 | F16: 17.783186 | G16: 244.57619 | H16: 44.729468 | I16: 45.240142 | J16: 54.271674 | K16: 73.964771 | L16: 58.424236 | M16: 21.954202 | N16: 41.195007 | O16: 39.880584 | P16: 47.19931 | Q16: 88.847165 | R16: 72.258564 | S16: 49.129874 | T16: 67.015428 | U16: 71.293067 | V16: 83.423156 | W16: 115.45875 | X16: 37.054087 | Y16: 27.233411 | Z16: 62.804758 | AA16: 26.990154 | AB16: 74.423893 | AC16: 143.99408 | AD16: 316.42064 | AE16: 70.449664 | AF16: 145.77008 | AG16: 57.020707 | AH16: 67.365176 | AI16: 78.364624 | AJ16: 111.00366 | AK16: 0 | AL16: 0 | AM16: 67.910554 | AN16: 123.72258 | AO16: 39.881131 | AP16: 0 | AQ16: 32.94756 | AR16: 0 | AS16: 31.83748 | AT16: 0 | AU16: 0 | AV16: 101.3539 | AW16: 40.013794 | AX16: 108.08453 | AY16: 108.6185 | AZ16: 102.35567 | BA16: 160.48687 | BB16: 124.90109 | BC16: 171.90289 | BD16: 119.93399
